>> python main.py
Traceback (most recent call last):
  File "C:\Python\Python313\Lib\site-packages\sqlalchemy\engine\base.py", line 145, in __init__
    self._dbapi_connection = engine.raw_connection()
                             ~~~~~~~~~~~~~~~~~~~~~^^
  File "C:\Python\Python313\Lib\site-packages\sqlalchemy\engine\base.py", line 3297, in raw_connection
    return self.pool.connect()
           ~~~~~~~~~~~~~~~~~^^
  File "C:\Python\Python313\Lib\site-packages\sqlalchemy\pool\base.py", line 449, in connect
    return _ConnectionFairy._checkout(self)
           ~~~~~~~~~~~~~~~~~~~~~~~~~~^^^^^^
  File "C:\Python\Python313\Lib\site-packages\sqlalchemy\pool\base.py", line 1264, in _checkout
    fairy = _ConnectionRecord.checkout(pool)
  File "C:\Python\Python313\Lib\site-packages\sqlalchemy\pool\base.py", line 713, in checkout
    rec = pool._do_get()
  File "C:\Python\Python313\Lib\site-packages\sqlalchemy\pool\impl.py", line 179, in _do_get
    with util.safe_reraise():
         ~~~~~~~~~~~~~~~~~^^
  File "C:\Python\Python313\Lib\site-packages\sqlalchemy\util\langhelpers.py", line 224, in __exit__      
    raise exc_value.with_traceback(exc_tb)
  File "C:\Python\Python313\Lib\site-packages\sqlalchemy\pool\impl.py", line 177, in _do_get
    return self._create_connection()
           ~~~~~~~~~~~~~~~~~~~~~~~^^
  File "C:\Python\Python313\Lib\site-packages\sqlalchemy\pool\base.py", line 390, in _create_connection   
    return _ConnectionRecord(self)
  File "C:\Python\Python313\Lib\site-packages\sqlalchemy\pool\base.py", line 675, in __init__
    self.__connect()
    ~~~~~~~~~~~~~~^^
  File "C:\Python\Python313\Lib\site-packages\sqlalchemy\pool\base.py", line 901, in __connect
    with util.safe_reraise():
         ~~~~~~~~~~~~~~~~~^^
  File "C:\Python\Python313\Lib\site-packages\sqlalchemy\util\langhelpers.py", line 224, in __exit__      
    raise exc_value.with_traceback(exc_tb)
  File "C:\Python\Python313\Lib\site-packages\sqlalchemy\pool\base.py", line 897, in __connect
    self.dbapi_connection = connection = pool._invoke_creator(self)
                                         ~~~~~~~~~~~~~~~~~~~~^^^^^^
  File "C:\Python\Python313\Lib\site-packages\sqlalchemy\engine\create.py", line 646, in connect
    return dialect.connect(*cargs, **cparams)
           ~~~~~~~~~~~~~~~^^^^^^^^^^^^^^^^^^^
  File "C:\Python\Python313\Lib\site-packages\sqlalchemy\engine\default.py", line 625, in connect
    return self.loaded_dbapi.connect(*cargs, **cparams)  # type: ignore[no-any-return]  # NOQA: E501      
           ~~~~~~~~~~~~~~~~~~~~~~~~~^^^^^^^^^^^^^^^^^^^
  File "C:\Python\Python313\Lib\site-packages\psycopg2\__init__.py", line 135, in connect
    conn = _connect(dsn, connection_factory=connection_factory, **kwasync)
psycopg2.OperationalError: could not translate host name "your_database_url_here" to address: Name or service not known


The above exception was the direct cause of the following exception:

Traceback (most recent call last):
  File "C:\Users\USER\AcademCheck (1)\AcademCheck\main.py", line 12, in <module>
    from app import app
  File "C:\Users\USER\AcademCheck (1)\AcademCheck\app.py", line 46, in <module>
    db.create_all()
    ~~~~~~~~~~~~~^^
  File "C:\Python\Python313\Lib\site-packages\flask_sqlalchemy\extension.py", line 900, in create_all     
    self._call_for_binds(bind_key, "create_all")
    ~~~~~~~~~~~~~~~~~~~~^^^^^^^^^^^^^^^^^^^^^^^^
  File "C:\Python\Python313\Lib\site-packages\flask_sqlalchemy\extension.py", line 881, in _call_for_binds
    getattr(metadata, op_name)(bind=engine)
    ~~~~~~~~~~~~~~~~~~~~~~~~~~^^^^^^^^^^^^^
  File "C:\Python\Python313\Lib\site-packages\sqlalchemy\sql\schema.py", line 5924, in create_all
    bind._run_ddl_visitor(
    ~~~~~~~~~~~~~~~~~~~~~^
        ddl.SchemaGenerator, self, checkfirst=checkfirst, tables=tables
        ^^^^^^^^^^^^^^^^^^^^^^^^^^^^^^^^^^^^^^^^^^^^^^^^^^^^^^^^^^^^^^^
    )
    ^
  File "C:\Python\Python313\Lib\site-packages\sqlalchemy\engine\base.py", line 3247, in _run_ddl_visitor  
    with self.begin() as conn:
         ~~~~~~~~~~^^
  File "C:\Python\Python313\Lib\contextlib.py", line 141, in __enter__
    return next(self.gen)
  File "C:\Python\Python313\Lib\site-packages\sqlalchemy\engine\base.py", line 3237, in begin
    with self.connect() as conn:
         ~~~~~~~~~~~~^^
  File "C:\Python\Python313\Lib\site-packages\sqlalchemy\engine\base.py", line 3273, in connect
    return self._connection_cls(self)
           ~~~~~~~~~~~~~~~~~~~~^^^^^^
  File "C:\Python\Python313\Lib\site-packages\sqlalchemy\engine\base.py", line 147, in __init__
    Connection._handle_dbapi_exception_noconnection(
    ~~~~~~~~~~~~~~~~~~~~~~~~~~~~~~~~~~~~~~~~~~~~~~~^
        err, dialect, engine
        ^^^^^^^^^^^^^^^^^^^^
    )
    ^
  File "C:\Python\Python313\Lib\site-packages\sqlalchemy\engine\base.py", line 2436, in _handle_dbapi_exception_noconnection
    raise sqlalchemy_exception.with_traceback(exc_info[2]) from e
  File "C:\Python\Python313\Lib\site-packages\sqlalchemy\engine\base.py", line 145, in __init__
    self._dbapi_connection = engine.raw_connection()
                             ~~~~~~~~~~~~~~~~~~~~~^^
  File "C:\Python\Python313\Lib\site-packages\sqlalchemy\engine\base.py", line 3297, in raw_connection    
    return self.pool.connect()
           ~~~~~~~~~~~~~~~~~^^
  File "C:\Python\Python313\Lib\site-packages\sqlalchemy\pool\base.py", line 449, in connect
    return _ConnectionFairy._checkout(self)
           ~~~~~~~~~~~~~~~~~~~~~~~~~~^^^^^^
  File "C:\Python\Python313\Lib\site-packages\sqlalchemy\pool\base.py", line 1264, in _checkout
    fairy = _ConnectionRecord.checkout(pool)
  File "C:\Python\Python313\Lib\site-packages\sqlalchemy\pool\base.py", line 713, in checkout
    rec = pool._do_get()
  File "C:\Python\Python313\Lib\site-packages\sqlalchemy\pool\impl.py", line 179, in _do_get
    with util.safe_reraise():
         ~~~~~~~~~~~~~~~~~^^
  File "C:\Python\Python313\Lib\site-packages\sqlalchemy\util\langhelpers.py", line 224, in __exit__      
    raise exc_value.with_traceback(exc_tb)
  File "C:\Python\Python313\Lib\site-packages\sqlalchemy\pool\impl.py", line 177, in _do_get
    return self._create_connection()
           ~~~~~~~~~~~~~~~~~~~~~~~^^
  File "C:\Python\Python313\Lib\site-packages\sqlalchemy\pool\base.py", line 390, in _create_connection   
    return _ConnectionRecord(self)
  File "C:\Python\Python313\Lib\site-packages\sqlalchemy\pool\base.py", line 675, in __init__
    self.__connect()
    ~~~~~~~~~~~~~~^^
  File "C:\Python\Python313\Lib\site-packages\sqlalchemy\pool\base.py", line 901, in __connect
    with util.safe_reraise():
         ~~~~~~~~~~~~~~~~~^^
  File "C:\Python\Python313\Lib\site-packages\sqlalchemy\util\langhelpers.py", line 224, in __exit__      
    raise exc_value.with_traceback(exc_tb)
  File "C:\Python\Python313\Lib\site-packages\sqlalchemy\pool\base.py", line 897, in __connect
    self.dbapi_connection = connection = pool._invoke_creator(self)
                                         ~~~~~~~~~~~~~~~~~~~~^^^^^^
  File "C:\Python\Python313\Lib\site-packages\sqlalchemy\engine\create.py", line 646, in connect
    return dialect.connect(*cargs, **cparams)
           ~~~~~~~~~~~~~~~^^^^^^^^^^^^^^^^^^^
  File "C:\Python\Python313\Lib\site-packages\sqlalchemy\engine\default.py", line 625, in connect
    return self.loaded_dbapi.connect(*cargs, **cparams)  # type: ignore[no-any-return]  # NOQA: E501      
           ~~~~~~~~~~~~~~~~~~~~~~~~~^^^^^^^^^^^^^^^^^^^
  File "C:\Python\Python313\Lib\site-packages\psycopg2\__init__.py", line 135, in connect
    conn = _connect(dsn, connection_factory=connection_factory, **kwasync)
sqlalchemy.exc.OperationalError: (psycopg2.OperationalError) could not translate host name "your_database_url_here" to address: Name or service not known

(Background on this error at: https://sqlalche.me/e/20/e3q8)